Traceback (most recent call last):
  File "C:\Users\12032\Downloads\WPy64-31050\python-3.10.5.amd64\lib\site-packages\jupyter_cache\executors\utils.py", line 58, in single_nb_execution
    executenb(
  File "C:\Users\12032\Downloads\WPy64-31050\python-3.10.5.amd64\lib\site-packages\nbclient\client.py", line 1204, in execute
    return NotebookClient(nb=nb, resources=resources, km=km, **kwargs).execute()
  File "C:\Users\12032\Downloads\WPy64-31050\python-3.10.5.amd64\lib\site-packages\nbclient\util.py", line 84, in wrapped
    return just_run(coro(*args, **kwargs))
  File "C:\Users\12032\Downloads\WPy64-31050\python-3.10.5.amd64\lib\site-packages\nbclient\util.py", line 62, in just_run
    return loop.run_until_complete(coro)
  File "C:\Users\12032\Downloads\WPy64-31050\python-3.10.5.amd64\lib\asyncio\base_events.py", line 646, in run_until_complete
    return future.result()
  File "C:\Users\12032\Downloads\WPy64-31050\python-3.10.5.amd64\lib\site-packages\nbclient\client.py", line 663, in async_execute
    await self.async_execute_cell(
  File "C:\Users\12032\Downloads\WPy64-31050\python-3.10.5.amd64\lib\site-packages\nbclient\client.py", line 965, in async_execute_cell
    await self._check_raise_for_error(cell, cell_index, exec_reply)
  File "C:\Users\12032\Downloads\WPy64-31050\python-3.10.5.amd64\lib\site-packages\nbclient\client.py", line 862, in _check_raise_for_error
    raise CellExecutionError.from_cell_and_msg(cell, exec_reply_content)
nbclient.exceptions.CellExecutionError: An error occurred while executing the following cell:
------------------
## Checking the best clustering of data

number_clust = range(2,20)
inertia = []

for num in number_clust:
    kmeans = KMeans(n_clusters = num,random_state = 300) #Creates Clusters and fits data
    kmeans = kmeans.fit(X_train)
    u = kmeans.inertia_
    inertia.append(u)
    
    print('The inertia for : ', num, ' clusters is: ', u)
------------------

[1;31m---------------------------------------------------------------------------[0m
[1;31mNameError[0m                                 Traceback (most recent call last)
[1;32m~\AppData\Local\Temp\ipykernel_4332\2719671876.py[0m in [0;36m<cell line: 6>[1;34m()[0m
[0;32m      6[0m [1;32mfor[0m [0mnum[0m [1;32min[0m [0mnumber_clust[0m[1;33m:[0m[1;33m[0m[1;33m[0m[0m
[0;32m      7[0m     [0mkmeans[0m [1;33m=[0m [0mKMeans[0m[1;33m([0m[0mn_clusters[0m [1;33m=[0m [0mnum[0m[1;33m,[0m[0mrandom_state[0m [1;33m=[0m [1;36m300[0m[1;33m)[0m [1;31m#Creates Clusters and fits data[0m[1;33m[0m[1;33m[0m[0m
[1;32m----> 8[1;33m     [0mkmeans[0m [1;33m=[0m [0mkmeans[0m[1;33m.[0m[0mfit[0m[1;33m([0m[0mX_train[0m[1;33m)[0m[1;33m[0m[1;33m[0m[0m
[0m[0;32m      9[0m     [0mu[0m [1;33m=[0m [0mkmeans[0m[1;33m.[0m[0minertia_[0m[1;33m[0m[1;33m[0m[0m
[0;32m     10[0m     [0minertia[0m[1;33m.[0m[0mappend[0m[1;33m([0m[0mu[0m[1;33m)[0m[1;33m[0m[1;33m[0m[0m

[1;31mNameError[0m: name 'X_train' is not defined
NameError: name 'X_train' is not defined

